에러가 발생하면 에러에 대한 정보를 name과 message라는 프로퍼티로 담고 있는 에러 객체가 만들어진다.  
대표적인 에러 객체는 SyntaxError, ReferenceError, TypeError 등이 있다.

에러 객체는 직접 만들 수도 있다.  
new 키워드와 에러 객체 이름을 딴 함수를 통해 에러 객체를 만들 수 있고, throw 키워드로 에러를 발생시킬 수 있다.
```javascript
throw new TypeError('타입 에러가 발생했습니다.');
```

# try catch문
```javascript
try {
  // 실행할 코드
} catch (error) {
  // 에러 발생 시 동작할 코드
}
```
try문에서 발생한 에러 객체가 catch문의 첫 번째 파라미터로 전달된다. 만약 try 문에서 에러가 발생하지 않을 경우 catch 문의 코드는 동작하지 않는다.

# finally 문
finally 문은 try catch 문이 끝난 다음 최종적으로 실행될 코드를 다룰 때 사용한다.

```javascript
try {
  // 실행할 코드
} catch (err) {
  // 에러가 발상했을 때 실행할 코드
} finally {
  // 항상 실행할 코드
}
```
try문에서 에러가 발생하지 않는다면 try문의 코드****가 모두 실행된 다음에,  
try문에서 에러가 발생한다면 catch문의 코드가 모두 실행된 다음 실행할 코드를 finally문에 작성하면 된다.

예제
```javascript
try {
  // 숫자를 입력받는 함수
  function inputNumber() {
    const number = parseInt(prompt("숫자를 입력하세요: "));
    if (isNaN(number)) {
      throw new Error("숫자가 아닙니다!");
    }
    return number;
  }

  // 함수 실행 및 에러 처리
  const number = inputNumber();
  console.log(`입력한 숫자는 ${number}입니다.`);
} catch (err) {
  // 에러 메시지 출력
  console.error(err.message);
} finally {
  // 숫자 입력 여부에 관계없이 항상 실행
  console.log("숫자 입력을 종료합니다.");
}
```

## finally 문에서의 에러 처리
finally문에서 에러가 발생할 경우에는 다시 그 위에 있는 catch문으로 넘어가진 않는다.
만약 finally문에서도 에러 처리가 필요한 경우에는 아래 처럼 try catch문을 중첩해서 활용하는 방법이 있다.

```javascript
try {
  try {
    // 실행할 코드
  } catch (err) {
    // 에러가 발상했을 때 실행할 코드
  } finally {
    // 항상 실행할 코드
  }
} catch (err) {
  // finally문에서 에러가 발생했을 때 실행할 코드
}
```
